is it just me or is it odd that assert.doesNotThrow() accepts an 'error' argument? and why is it documented?