assert.throws: does it re-throw exception if expected!=actual or does it throw AssertionError in that case?