it's a little confusing because it seems like maybe the try should prevent the error from throwing, and the "run" will exit the domain for you.  but, the callback happens later, asynchronously, after the run has completed