asdf12 I've placed the defective code inside a try container and for the catch y just catch(e){ throw e;} â€¦. I still get the same behavior 