I guess it might be some patching done by the packager: unfortunately archlinux moved to python3 a little bit too hastily